[2025-08-06T15:26:59.329+0530] {taskinstance.py:1979} INFO - Dependencies all met for dep_context=non-requeueable deps ti=<TaskInstance: mssql_to_snowflake_retail_sales.extract_data_from_mssql manual__2025-08-06T09:51:54.099852+00:00 [queued]>
[2025-08-06T15:26:59.332+0530] {taskinstance.py:1979} INFO - Dependencies all met for dep_context=requeueable deps ti=<TaskInstance: mssql_to_snowflake_retail_sales.extract_data_from_mssql manual__2025-08-06T09:51:54.099852+00:00 [queued]>
[2025-08-06T15:26:59.332+0530] {taskinstance.py:2193} INFO - Starting attempt 2 of 2
[2025-08-06T15:26:59.337+0530] {taskinstance.py:2214} INFO - Executing <Task(PythonOperator): extract_data_from_mssql> on 2025-08-06 09:51:54.099852+00:00
[2025-08-06T15:26:59.341+0530] {standard_task_runner.py:60} INFO - Started process 17255 to run task
[2025-08-06T15:26:59.348+0530] {standard_task_runner.py:87} INFO - Running: ['airflow', 'tasks', 'run', 'mssql_to_snowflake_retail_sales', 'extract_data_from_mssql', 'manual__2025-08-06T09:51:54.099852+00:00', '--job-id', '9', '--raw', '--subdir', 'DAGS_FOLDER/mssql_to_snowflake_retail_sales.py', '--cfg-path', '/var/folders/mm/zzj9zbr97855tkztpv4m513r0000gp/T/tmpzx1vngmz']
[2025-08-06T15:26:59.350+0530] {standard_task_runner.py:88} INFO - Job 9: Subtask extract_data_from_mssql
[2025-08-06T15:26:59.376+0530] {task_command.py:423} INFO - Running <TaskInstance: mssql_to_snowflake_retail_sales.extract_data_from_mssql manual__2025-08-06T09:51:54.099852+00:00 [running]> on host dq-macbooks-macbook-air-5.local
[2025-08-06T15:26:59.402+0530] {taskinstance.py:2510} INFO - Exporting env vars: AIRFLOW_CTX_DAG_EMAIL='your-email@example.com' AIRFLOW_CTX_DAG_OWNER='airflow' AIRFLOW_CTX_DAG_ID='mssql_to_snowflake_retail_sales' AIRFLOW_CTX_TASK_ID='extract_data_from_mssql' AIRFLOW_CTX_EXECUTION_DATE='2025-08-06T09:51:54.099852+00:00' AIRFLOW_CTX_TRY_NUMBER='2' AIRFLOW_CTX_DAG_RUN_ID='manual__2025-08-06T09:51:54.099852+00:00'
[2025-08-06T15:26:59.403+0530] {taskinstance.py:2728} ERROR - Task failed with exception
Traceback (most recent call last):
  File "/Users/sureshduddu/Cursor/airflow/.venv/lib/python3.10/site-packages/airflow/models/taskinstance.py", line 444, in _execute_task
    result = _execute_callable(context=context, **execute_callable_kwargs)
  File "/Users/sureshduddu/Cursor/airflow/.venv/lib/python3.10/site-packages/airflow/models/taskinstance.py", line 414, in _execute_callable
    return execute_callable(context=context, **execute_callable_kwargs)
  File "/Users/sureshduddu/Cursor/airflow/.venv/lib/python3.10/site-packages/airflow/operators/python.py", line 200, in execute
    return_value = self.execute_callable()
  File "/Users/sureshduddu/Cursor/airflow/.venv/lib/python3.10/site-packages/airflow/operators/python.py", line 217, in execute_callable
    return self.python_callable(*self.op_args, **self.op_kwargs)
  File "/Users/sureshduddu/Cursor/airflow/dags/mssql_to_snowflake_retail_sales.py", line 67, in extract_data_from_mssql
    import pyodbc
ImportError: dlopen(/Users/sureshduddu/Cursor/airflow/.venv/lib/python3.10/site-packages/pyodbc.cpython-310-darwin.so, 0x0002): Library not loaded: /opt/homebrew/opt/unixodbc/lib/libodbc.2.dylib
  Referenced from: <B0C2BFCC-FE64-3B53-9DE8-6EA39AA036E8> /Users/sureshduddu/Cursor/airflow/.venv/lib/python3.10/site-packages/pyodbc.cpython-310-darwin.so
  Reason: tried: '/opt/homebrew/opt/unixodbc/lib/libodbc.2.dylib' (no such file), '/System/Volumes/Preboot/Cryptexes/OS/opt/homebrew/opt/unixodbc/lib/libodbc.2.dylib' (no such file), '/opt/homebrew/opt/unixodbc/lib/libodbc.2.dylib' (no such file)
[2025-08-06T15:26:59.406+0530] {taskinstance.py:1149} INFO - Marking task as FAILED. dag_id=mssql_to_snowflake_retail_sales, task_id=extract_data_from_mssql, execution_date=20250806T095154, start_date=20250806T095659, end_date=20250806T095659
[2025-08-06T15:26:59.415+0530] {logging_mixin.py:188} WARNING - /Users/sureshduddu/Cursor/airflow/.venv/lib/python3.10/site-packages/airflow/utils/email.py:154 RemovedInAirflow3Warning: Fetching SMTP credentials from configuration variables will be deprecated in a future release. Please set credentials using a connection instead.
[2025-08-06T15:26:59.415+0530] {configuration.py:1046} WARNING - section/key [smtp/smtp_user] not found in config
[2025-08-06T15:26:59.415+0530] {email.py:270} INFO - Email alerting: attempt 1
[2025-08-06T15:26:59.418+0530] {configuration.py:1046} WARNING - section/key [smtp/smtp_user] not found in config
[2025-08-06T15:26:59.418+0530] {email.py:270} INFO - Email alerting: attempt 1
[2025-08-06T15:26:59.419+0530] {taskinstance.py:837} ERROR - Failed to send email to: ['your-email@example.com']
Traceback (most recent call last):
  File "/Users/sureshduddu/Cursor/airflow/.venv/lib/python3.10/site-packages/airflow/models/taskinstance.py", line 2357, in _run_raw_task
    self._execute_task_with_callbacks(context, test_mode, session=session)
  File "/Users/sureshduddu/Cursor/airflow/.venv/lib/python3.10/site-packages/airflow/models/taskinstance.py", line 2529, in _execute_task_with_callbacks
    result = self._execute_task(context, task_orig)
  File "/Users/sureshduddu/Cursor/airflow/.venv/lib/python3.10/site-packages/airflow/models/taskinstance.py", line 2546, in _execute_task
    return _execute_task(self, context, task_orig)
  File "/Users/sureshduddu/Cursor/airflow/.venv/lib/python3.10/site-packages/airflow/models/taskinstance.py", line 444, in _execute_task
    result = _execute_callable(context=context, **execute_callable_kwargs)
  File "/Users/sureshduddu/Cursor/airflow/.venv/lib/python3.10/site-packages/airflow/models/taskinstance.py", line 414, in _execute_callable
    return execute_callable(context=context, **execute_callable_kwargs)
  File "/Users/sureshduddu/Cursor/airflow/.venv/lib/python3.10/site-packages/airflow/operators/python.py", line 200, in execute
    return_value = self.execute_callable()
  File "/Users/sureshduddu/Cursor/airflow/.venv/lib/python3.10/site-packages/airflow/operators/python.py", line 217, in execute_callable
    return self.python_callable(*self.op_args, **self.op_kwargs)
  File "/Users/sureshduddu/Cursor/airflow/dags/mssql_to_snowflake_retail_sales.py", line 67, in extract_data_from_mssql
    import pyodbc
ImportError: dlopen(/Users/sureshduddu/Cursor/airflow/.venv/lib/python3.10/site-packages/pyodbc.cpython-310-darwin.so, 0x0002): Library not loaded: /opt/homebrew/opt/unixodbc/lib/libodbc.2.dylib
  Referenced from: <B0C2BFCC-FE64-3B53-9DE8-6EA39AA036E8> /Users/sureshduddu/Cursor/airflow/.venv/lib/python3.10/site-packages/pyodbc.cpython-310-darwin.so
  Reason: tried: '/opt/homebrew/opt/unixodbc/lib/libodbc.2.dylib' (no such file), '/System/Volumes/Preboot/Cryptexes/OS/opt/homebrew/opt/unixodbc/lib/libodbc.2.dylib' (no such file), '/opt/homebrew/opt/unixodbc/lib/libodbc.2.dylib' (no such file)

During handling of the above exception, another exception occurred:

Traceback (most recent call last):
  File "/Users/sureshduddu/Cursor/airflow/.venv/lib/python3.10/site-packages/airflow/models/taskinstance.py", line 1011, in _email_alert
    send_email(task.email, subject, html_content)
  File "/Users/sureshduddu/Cursor/airflow/.venv/lib/python3.10/site-packages/airflow/utils/email.py", line 80, in send_email
    return backend(
  File "/Users/sureshduddu/Cursor/airflow/.venv/lib/python3.10/site-packages/airflow/utils/email.py", line 154, in send_email_smtp
    send_mime_email(e_from=mail_from, e_to=recipients, mime_msg=msg, conn_id=conn_id, dryrun=dryrun)
  File "/Users/sureshduddu/Cursor/airflow/.venv/lib/python3.10/site-packages/airflow/utils/email.py", line 272, in send_mime_email
    smtp_conn = _get_smtp_connection(smtp_host, smtp_port, smtp_timeout, smtp_ssl)
  File "/Users/sureshduddu/Cursor/airflow/.venv/lib/python3.10/site-packages/airflow/utils/email.py", line 316, in _get_smtp_connection
    return smtplib.SMTP(host=host, port=port, timeout=timeout)
  File "/Library/Frameworks/Python.framework/Versions/3.10/lib/python3.10/smtplib.py", line 255, in __init__
    (code, msg) = self.connect(host, port)
  File "/Library/Frameworks/Python.framework/Versions/3.10/lib/python3.10/smtplib.py", line 341, in connect
    self.sock = self._get_socket(host, port, self.timeout)
  File "/Library/Frameworks/Python.framework/Versions/3.10/lib/python3.10/smtplib.py", line 312, in _get_socket
    return socket.create_connection((host, port), timeout,
  File "/Library/Frameworks/Python.framework/Versions/3.10/lib/python3.10/socket.py", line 845, in create_connection
    raise err
  File "/Library/Frameworks/Python.framework/Versions/3.10/lib/python3.10/socket.py", line 833, in create_connection
    sock.connect(sa)
ConnectionRefusedError: [Errno 61] Connection refused

During handling of the above exception, another exception occurred:

Traceback (most recent call last):
  File "/Users/sureshduddu/Cursor/airflow/.venv/lib/python3.10/site-packages/airflow/models/taskinstance.py", line 835, in _handle_failure
    task_instance.email_alert(error, failure_context["task"])
  File "/Users/sureshduddu/Cursor/airflow/.venv/lib/python3.10/site-packages/airflow/models/taskinstance.py", line 2976, in email_alert
    _email_alert(task_instance=self, exception=exception, task=task)
  File "/Users/sureshduddu/Cursor/airflow/.venv/lib/python3.10/site-packages/airflow/models/taskinstance.py", line 1013, in _email_alert
    send_email(task.email, subject, html_content_err)
  File "/Users/sureshduddu/Cursor/airflow/.venv/lib/python3.10/site-packages/airflow/utils/email.py", line 80, in send_email
    return backend(
  File "/Users/sureshduddu/Cursor/airflow/.venv/lib/python3.10/site-packages/airflow/utils/email.py", line 154, in send_email_smtp
    send_mime_email(e_from=mail_from, e_to=recipients, mime_msg=msg, conn_id=conn_id, dryrun=dryrun)
  File "/Users/sureshduddu/Cursor/airflow/.venv/lib/python3.10/site-packages/airflow/utils/email.py", line 272, in send_mime_email
    smtp_conn = _get_smtp_connection(smtp_host, smtp_port, smtp_timeout, smtp_ssl)
  File "/Users/sureshduddu/Cursor/airflow/.venv/lib/python3.10/site-packages/airflow/utils/email.py", line 316, in _get_smtp_connection
    return smtplib.SMTP(host=host, port=port, timeout=timeout)
  File "/Library/Frameworks/Python.framework/Versions/3.10/lib/python3.10/smtplib.py", line 255, in __init__
    (code, msg) = self.connect(host, port)
  File "/Library/Frameworks/Python.framework/Versions/3.10/lib/python3.10/smtplib.py", line 341, in connect
    self.sock = self._get_socket(host, port, self.timeout)
  File "/Library/Frameworks/Python.framework/Versions/3.10/lib/python3.10/smtplib.py", line 312, in _get_socket
    return socket.create_connection((host, port), timeout,
  File "/Library/Frameworks/Python.framework/Versions/3.10/lib/python3.10/socket.py", line 845, in create_connection
    raise err
  File "/Library/Frameworks/Python.framework/Versions/3.10/lib/python3.10/socket.py", line 833, in create_connection
    sock.connect(sa)
ConnectionRefusedError: [Errno 61] Connection refused
[2025-08-06T15:26:59.425+0530] {standard_task_runner.py:107} ERROR - Failed to execute job 9 for task extract_data_from_mssql (dlopen(/Users/sureshduddu/Cursor/airflow/.venv/lib/python3.10/site-packages/pyodbc.cpython-310-darwin.so, 0x0002): Library not loaded: /opt/homebrew/opt/unixodbc/lib/libodbc.2.dylib
  Referenced from: <B0C2BFCC-FE64-3B53-9DE8-6EA39AA036E8> /Users/sureshduddu/Cursor/airflow/.venv/lib/python3.10/site-packages/pyodbc.cpython-310-darwin.so
  Reason: tried: '/opt/homebrew/opt/unixodbc/lib/libodbc.2.dylib' (no such file), '/System/Volumes/Preboot/Cryptexes/OS/opt/homebrew/opt/unixodbc/lib/libodbc.2.dylib' (no such file), '/opt/homebrew/opt/unixodbc/lib/libodbc.2.dylib' (no such file); 17255)
[2025-08-06T15:26:59.439+0530] {local_task_job_runner.py:234} INFO - Task exited with return code 1
[2025-08-06T15:26:59.447+0530] {taskinstance.py:3309} INFO - 0 downstream tasks scheduled from follow-on schedule check
